<mujoco model="g1 inspirehand drawer scene">
  <include file="g1_inspirehands_fixed.xml"/>
  <option gravity="0 0 -9.81"/>
  <statistic center="1.0 0.7 1.0" extent="0.8"/>

  <visual>
    <headlight diffuse="0.6 0.6 0.6" ambient="0.1 0.1 0.1" specular="0.9 0.9 0.9"/>
    <rgba haze="0.15 0.25 0.35 1"/>
    <global azimuth="-140" elevation="-20"/>
  </visual>

  <asset>
    <texture type="skybox" builtin="flat" rgb1="0 0 0" rgb2="0 0 0" width="512" height="3072"/>
    <texture type="2d" name="groundplane" builtin="checker" mark="edge" rgb1="0.2 0.3 0.4" rgb2="0.1 0.2 0.3" markrgb="0.8 0.8 0.8" width="300" height="300"/>
    <material name="groundplane" texture="groundplane" texuniform="true" texrepeat="5 5" reflectance="0.2"/>
  </asset>

  <worldbody>
    <light pos="1 0 3.5" dir="0 0 -1" directional="true"/>
    <geom name="floor" size="0 0 0.05" type="plane" material="groundplane"/>

    <body name="drawer_visual" pos="0.68 -0.15 0.753">
      <geom name="drawer_cabinet" type="box" size="0.12 0.16 0.11" rgba="0.22 0.22 0.24 1" contype="0" conaffinity="0"/>
    </body>

    <body name="object" pos="0.59 -0.15 0.753">
      <joint name="object_slide_x" type="slide" axis="1 0 0" range="-0.25 0.03" damping="0.2"/>
      <geom name="drawer_front" pos="0 0 0" type="box" size="0.015 0.14 0.09" rgba="0.55 0.55 0.58 1" friction="1 0.005 0.0001" mass="0.4"/>
      <geom name="drawer_handle_left_post" pos="-0.055 -0.075 -0.04" type="box" size="0.02 0.012 0.045" rgba="0.05 0.05 0.05 1" friction="1 0.005 0.0001"/>
      <geom name="drawer_handle_right_post" pos="-0.055 0.075 -0.04" type="box" size="0.02 0.012 0.045" rgba="0.05 0.05 0.05 1" friction="1 0.005 0.0001"/>
      <geom name="drawer_handle_bar" pos="-0.09 0 0.005" type="box" size="0.025 0.095 0.014" rgba="0.02 0.02 0.02 1" friction="1 0.005 0.0001"/>
    </body>
  </worldbody>
</mujoco>
